[2021-08-26 00:24:11,205] {taskinstance.py:876} INFO - Dependencies all met for <TaskInstance: test_dag.t1 2021-08-26T00:24:10.146027+00:00 [queued]>
[2021-08-26 00:24:11,215] {taskinstance.py:876} INFO - Dependencies all met for <TaskInstance: test_dag.t1 2021-08-26T00:24:10.146027+00:00 [queued]>
[2021-08-26 00:24:11,216] {taskinstance.py:1067} INFO - 
--------------------------------------------------------------------------------
[2021-08-26 00:24:11,217] {taskinstance.py:1068} INFO - Starting attempt 1 of 1
[2021-08-26 00:24:11,219] {taskinstance.py:1069} INFO - 
--------------------------------------------------------------------------------
[2021-08-26 00:24:11,231] {taskinstance.py:1087} INFO - Executing <Task(PythonOperator): t1> on 2021-08-26T00:24:10.146027+00:00
[2021-08-26 00:24:11,237] {standard_task_runner.py:52} INFO - Started process 586 to run task
[2021-08-26 00:24:11,242] {standard_task_runner.py:76} INFO - Running: ['***', 'tasks', 'run', 'test_dag', 't1', '2021-08-26T00:24:10.146027+00:00', '--job-id', '19', '--pool', 'default_pool', '--raw', '--subdir', 'DAGS_FOLDER/test_dag.py', '--cfg-path', '/tmp/tmplig18kux', '--error-file', '/tmp/tmp7a2tj8o2']
[2021-08-26 00:24:11,243] {standard_task_runner.py:77} INFO - Job 19: Subtask t1
[2021-08-26 00:24:11,290] {logging_mixin.py:104} INFO - Running <TaskInstance: test_dag.t1 2021-08-26T00:24:10.146027+00:00 [running]> on host f913d28eb98c
[2021-08-26 00:24:11,370] {taskinstance.py:1282} INFO - Exporting the following env vars:
AIRFLOW_CTX_DAG_OWNER=dini
AIRFLOW_CTX_DAG_ID=test_dag
AIRFLOW_CTX_TASK_ID=t1
AIRFLOW_CTX_EXECUTION_DATE=2021-08-26T00:24:10.146027+00:00
AIRFLOW_CTX_DAG_RUN_ID=manual__2021-08-26T00:24:10.146027+00:00
[2021-08-26 00:24:11,381] {taskinstance.py:1481} ERROR - Task failed with exception
Traceback (most recent call last):
  File "/home/airflow/.local/lib/python3.6/site-packages/urllib3/connection.py", line 160, in _new_conn
    (self._dns_host, self.port), self.timeout, **extra_kw
  File "/home/airflow/.local/lib/python3.6/site-packages/urllib3/util/connection.py", line 84, in create_connection
    raise err
  File "/home/airflow/.local/lib/python3.6/site-packages/urllib3/util/connection.py", line 74, in create_connection
    sock.connect(sa)
ConnectionRefusedError: [Errno 111] Connection refused

During handling of the above exception, another exception occurred:

Traceback (most recent call last):
  File "/home/airflow/.local/lib/python3.6/site-packages/urllib3/connectionpool.py", line 677, in urlopen
    chunked=chunked,
  File "/home/airflow/.local/lib/python3.6/site-packages/urllib3/connectionpool.py", line 392, in _make_request
    conn.request(method, url, **httplib_request_kw)
  File "/usr/local/lib/python3.6/http/client.py", line 1287, in request
    self._send_request(method, url, body, headers, encode_chunked)
  File "/usr/local/lib/python3.6/http/client.py", line 1333, in _send_request
    self.endheaders(body, encode_chunked=encode_chunked)
  File "/usr/local/lib/python3.6/http/client.py", line 1282, in endheaders
    self._send_output(message_body, encode_chunked=encode_chunked)
  File "/usr/local/lib/python3.6/http/client.py", line 1042, in _send_output
    self.send(msg)
  File "/usr/local/lib/python3.6/http/client.py", line 980, in send
    self.connect()
  File "/home/airflow/.local/lib/python3.6/site-packages/urllib3/connection.py", line 187, in connect
    conn = self._new_conn()
  File "/home/airflow/.local/lib/python3.6/site-packages/urllib3/connection.py", line 172, in _new_conn
    self, "Failed to establish a new connection: %s" % e
urllib3.exceptions.NewConnectionError: <urllib3.connection.HTTPConnection object at 0x7f93e00e9a58>: Failed to establish a new connection: [Errno 111] Connection refused

During handling of the above exception, another exception occurred:

Traceback (most recent call last):
  File "/home/airflow/.local/lib/python3.6/site-packages/requests/adapters.py", line 449, in send
    timeout=timeout
  File "/home/airflow/.local/lib/python3.6/site-packages/urllib3/connectionpool.py", line 727, in urlopen
    method, url, error=e, _pool=self, _stacktrace=sys.exc_info()[2]
  File "/home/airflow/.local/lib/python3.6/site-packages/urllib3/util/retry.py", line 446, in increment
    raise MaxRetryError(_pool, url, error or ResponseError(cause))
urllib3.exceptions.MaxRetryError: HTTPConnectionPool(host='localhost', port=5000): Max retries exceeded with url: /insert (Caused by NewConnectionError('<urllib3.connection.HTTPConnection object at 0x7f93e00e9a58>: Failed to establish a new connection: [Errno 111] Connection refused',))

During handling of the above exception, another exception occurred:

Traceback (most recent call last):
  File "/home/airflow/.local/lib/python3.6/site-packages/airflow/models/taskinstance.py", line 1137, in _run_raw_task
    self._prepare_and_execute_task_with_callbacks(context, task)
  File "/home/airflow/.local/lib/python3.6/site-packages/airflow/models/taskinstance.py", line 1311, in _prepare_and_execute_task_with_callbacks
    result = self._execute_task(context, task_copy)
  File "/home/airflow/.local/lib/python3.6/site-packages/airflow/models/taskinstance.py", line 1341, in _execute_task
    result = task_copy.execute(context=context)
  File "/home/airflow/.local/lib/python3.6/site-packages/airflow/operators/python.py", line 150, in execute
    return_value = self.execute_callable()
  File "/home/airflow/.local/lib/python3.6/site-packages/airflow/operators/python.py", line 161, in execute_callable
    return self.python_callable(*self.op_args, **self.op_kwargs)
  File "/opt/airflow/dags/test_dag.py", line 11, in insert_data
    requests.post(url=url, data=datas)
  File "/home/airflow/.local/lib/python3.6/site-packages/requests/api.py", line 119, in post
    return request('post', url, data=data, json=json, **kwargs)
  File "/home/airflow/.local/lib/python3.6/site-packages/requests/api.py", line 61, in request
    return session.request(method=method, url=url, **kwargs)
  File "/home/airflow/.local/lib/python3.6/site-packages/requests/sessions.py", line 542, in request
    resp = self.send(prep, **send_kwargs)
  File "/home/airflow/.local/lib/python3.6/site-packages/requests/sessions.py", line 655, in send
    r = adapter.send(request, **kwargs)
  File "/home/airflow/.local/lib/python3.6/site-packages/requests/adapters.py", line 516, in send
    raise ConnectionError(e, request=request)
requests.exceptions.ConnectionError: HTTPConnectionPool(host='localhost', port=5000): Max retries exceeded with url: /insert (Caused by NewConnectionError('<urllib3.connection.HTTPConnection object at 0x7f93e00e9a58>: Failed to establish a new connection: [Errno 111] Connection refused',))
[2021-08-26 00:24:11,396] {taskinstance.py:1531} INFO - Marking task as FAILED. dag_id=test_dag, task_id=t1, execution_date=20210826T002410, start_date=20210826T002411, end_date=20210826T002411
[2021-08-26 00:24:11,455] {local_task_job.py:151} INFO - Task exited with return code 1
